Workbook

Sheet Data
A1: Name | B1: FinancialYear | C1: AsAt | D1: StartDate | E1: ShareCapital | F1: StatutoryReserve | G1: Otherreserves | H1: retainedEarnins | I1: NetSurplusaftertax | J1: LoansandAdvances | K1: totalassetsPBSheet | L1: Cash | M1: PropertyandEquipment | N1: GovernmentSecurities | O1: DepositsandBalancesatOtherInstitutions | P1: Otherassets | Q1: CapitalGrants | R1: InvestmentsinSubsidiary | S1: OFFBALANCESHEETASSETS | T1: TOTALOnBalanceSheet | U1: OtherDeductions | V1: Sub_Total | W1: TotalDeductions | X1: CORECAPITAL | Y1: RetainedearningsandDisclosedreserves | Z1: TotalAssets | AA1: TotalDepositsLiabilities | AB1: CorecapitaltoAssetsRatio | AC1: MinimumCoreCapitaltoAssetsRatioRequirement | AD1: Excess1 | AE1: RetainedearningsanddisclosedreservestoCorecapital | AF1: MinimumRetainedearningsanddisclosed | AG1: Excess2 | AH1: CorecapitatoDepositsRatio | AI1: MinimumCoreCapitaltoDeposits | AJ1: Excess

Sheet Capital Adequacy Report
B1: FORM 2A (r.13 (1))
C2: CAPITAL ADEQUACY RETURN
C3: NAME OF SACCO SOCIETY: | D3: =Data[Name] -> 0
C4: SACCO SOCIETY CS NUMBER: | D4: 2259
C5: FINANCIAL YEAR: | D5: =Data[FinancialYear] -> 0
C6: START DATE: | D6: =Data[StartDate] -> 0
C7: END DATE: | D7: =Data[AsAt] -> 0
D8: AMOUNT(KSHS)
B9: 1 | C9: CAPITAL COMPONENTS
B10: 1.1 | C10: CORE CAPITAL
B11: 1.1.1 | C11: Share Capital | D11: =SUM(Data!E2) -> 0
B12: 1.1.2 | C12: Capital Grants(Equity in nature) | D12: =SUM(Data!Q2) -> 0
B13: 1.1.3 | C13: Retained earnings/Accumulated losses | D13: =SUM(Data!H2) -> 0
B14: 1.1.4 | C14: Net Surplus after tax , current year to-date ( 50% ) | D14: =SUM(Data!I2) -> 0
B15: 1.1.5 | C15: Statutory Reserves | D15: =SUM(Data!F2) -> 0
B16: 1.1.6 | C16: Other reserves (Include all loss) | D16: =SUM(Data!G2) -> 0
B17: 1.1.7 | C17: Sub-Total (1.1.1 to 1.1.6) | D17: =SUM(D11:D16) -> 0
C18: LESS DEDUCTIONS
B19: 1.1.8 | C19: Investments in Subsidiary and Equity instruments of other Institutions | D19: =SUM(Data!Q2) -> 0
B20: 1.1.9 | C20: Other Deductions | D20: =SUM(Data!U2) -> 0
B21: 1.1.10 | C21: Total Deductions (1.1.8 to 1.1.9) | D21: =D19+D20 -> 0
B22: 1.1.11 | C22: CORE CAPITAL (1.1.7 Less 1.1.10) | D22: =D17-D21 -> 0
B23: 1.1.12 | C23: Retained earnings and Disclosed reserves ( Sub total 1.1.2 to 1.1.6) | D23: =D12+D13+D14+D15+D16 -> 0
B25: 2 | C25: ON - BALANCE SHEET ASSETS
B26: 2.1 | C26: Cash (Local + Foreign Currency) | D26: =SUM(Data!L2) -> 0
B27: 2.2 | C27: Government Securities | D27: =SUM(Data!N2) -> 0
B28: 2.3 | C28: Deposits and Balances at Other Institutions | D28: =SUM(Data!O2) -> 0
B29: 2.4 | C29: Loans and Advances | D29: =SUM(Data!J2) -> 0
B30: 2.5 | C30: Investments | D30: =SUM(Data!R2) -> 0
B31: 2.6 | C31: Property and Equipment (net of depreciation) | D31: =SUM(Data!M2) -> 0
B32: 2.7 | C32: Other assets | D32: =SUM(Data!P2) -> 0
B33: 2.8 | C33: TOTAL (2.1 to 2.7) | D33: =SUM(D26:D32) -> 0
B34: 2.9 | C34: Total Assets (Per Balance Sheet) | D34: =SUM(Data!T2) -> 0
B35: 3 | C35: Difference (2.8 Less 2.9)* | D35: =D33-D34 -> 0
B37: 3 | C37: OFF-BALANCE SHEET ASSETS | D37: =SUM(Data!S2) -> 0
B39: 4 | C39: CAPITAL RATIO CALCULATIONS
B41: 4.1 | C41: Total Asset value of on-balance sheet items as per 2.9 above | D41: =SUM(Data!T2) -> 0
B42: 4.2 | C42: Total Asset value of off-balance sheet items as per 3 above | D42: =SUM(Data!S2) -> 0
B43: 4.3 | C43: Total Assets (4.1 + 4.2) | D43: =SUM(D41:D42) -> 0
B44: 4.4 | C44: Total Deposits Liabilities (As per Balance Sheet) | D44: =SUM(Data!AA2) -> 0
...
