Workbook

Sheet Data
A1: ReportForNavId_1 | B1: AsAt | C1: Date | D1: FinancialYear | E1: Name | F1: InterestonLoanPortfolio | G1: FeesCommissiononLoanPortfolio | H1: GovernmentSecurities | I1: InvestmentinCompaniesshares | J1: EquityInvestmentsinsubsidiaries | K1: Derivatives | L1: CollectiveinvestmentSchemes | M1: CommercialPapers | N1: PlacementinBanks | O1: nterestExpenseonDeposits | P1: CostofExternalBorrowings | Q1: DividendExpenses | R1: OtherFinancialExpense | S1: FeesCommissionExpense | T1: OtherExpense | U1: ProvisionforLoanLosses | V1: ValueofLoansRecovered | W1: PersonnelExpenses | X1: GovernanceExpenses | Y1: MarketingExpenses | Z1: DepreciationandAmortizationCharges | AA1: AdministrativeExpenses | AB1: NonOperatingIncome | AC1: NonOperatingExpense | AD1: Taxes | AE1: Donations | AF1: FinancialIncomefromLoansPortfolio | AG1: FinancialExpense | AH1: NetFinancialIncomeLoss | AI1: NetNonOperatingIncomeExpense | AJ1: FinancialIncomefromInvestments | AK1: AllowanceforLoanLoss | AL1: OperatingExpenses | AM1: NetOperatingIncome | AN1: NetIncomeBeforeTaxesandDonations | AO1: NetIncomeAfterTaxesbeforeDonations | AP1: NetIncomeAfterTaxesandDonations | AQ1: FinancialIncome

Sheet Statement Of Compreh Income
A1: FORM 2F
A2: STATEMENT OF COMPREHENSIVE INCOME
A3: NAME OF SACCO SOCIETY | C3: =Data!E2 -> 0
A4: SACCO SOCIETY CS NUMBER | C4: 2259
A5: FINANCIAL YEAR | C5: =Data!D2 -> 0
A6: START DATE: | C6: =Data!C2 -> 0
A7: END DATE: | C7: =Data!B2 -> 0
A9: Ref No. | C9: Year to Date
C10: AMOUNT(KSHS)
A11: 1 | B11: Financial Income | C11: =C12+C16 -> 0
A12: 2 | B12: Financial Income from Loans Portfolio | C12: =SUM(C13:C14) -> 0
A13: 2.1 | B13: Interest on Loan Portfolio | C13: =SUM(Data!F2) -> 0
A14: 2.2 | B14: Fees & Commission on Loan Portfolio | C14: =SUM(Data!G2) -> 0
A16: 3 | B16: Financial Income from Investments | C16: =SUM(C17:C23) -> 0
A17: 3.1 | B17: Government Securities | C17: =SUM(Data!H2) -> 0
A18: 3.2 | B18: Placement in Banks, Saccos' and similar financial institutions | C18: =SUM(Data!N2) -> 0
A19: 3.3 | B19: Commercial Papers, notes and bonds | C19: =SUM(Data!M2) -> 0
A20: 3.4 | B20: Collective investment Schemes | C20: =SUM(Data!L2) -> 0
A21: 3.5 | B21: Derivatives | C21: =SUM(Data!K2) -> 0
A22: 3.6 | B22: Equity Investments in subsidiaries and related entities | C22: =SUM(Data!J2) -> 0
A23: 3.7 | B23: Investment in Companies shares | C23: =SUM(Data!I2) -> 0
A25: 4 | B25: Financial Expense | C25: =C26+C27+C28+C29+C30+C31 -> 0
A26: 4.1 | B26: Interest Expense on Deposits | C26: =SUM(Data!O2) -> 0
A27: 4.2 | B27: Cost of External Borrowings | C27: =SUM(Data!P2) -> 0
A28: 4.3 | B28: Dividend Expenses (on member shares) | C28: =SUM(Data!Q2) -> 0
A29: 4.4 | B29: Other Financial Expense | C29: =SUM(Data!R2) -> 0
A30: 4.5 | B30: Fees & Commission Expense | C30: =SUM(Data!S2) -> 0
A31: 4.6 | B31: Other Expense
A32: 5 | B32: Net Financial Income/(Loss) | C32: =C11-C25 -> 0
A34: 6 | B34: Allowance for Loan Loss | C34: =C35-C36 -> 0
A35: 6.1 | B35: Provision for Loan Losses | C35: =SUM(Data!U2) -> 0
A36: 6.2 | B36: Value of Loans Recovered | C36: =SUM(Data!V2) -> 0
A38: 7 | B38: Operating Expenses | C38: =SUM(C39:C43) -> 0
A39: 7.1 | B39: Personnel Expenses | C39: =SUM(Data!W2) -> 0
A40: 7.2 | B40: Governance Expenses | C40: =SUM(Data!X2) -> 0
A41: 7.3 | B41: Marketing Expenses | C41: =SUM(Data!Y2) -> 0
A42: 7.4 | B42: Depreciation and Amortization Charges | C42: =SUM(Data!Z2) -> 0
A43: 7.5 | B43: Administrative Expenses | C43: =SUM(Data!AA2) -> 0
A45: 8 | B45: Net Operating Income | C45: =C32-C34-C38 -> 0
A47: 9 | B47: Net Non- Operating Income/ (Expense) | C47: =C48-C49 -> 0
...
