Workbook

Sheet Data
A1: ReportForNavId_1 | B1: AsAt | C1: Date | D1: FinancialYear | E1: name | F1: Grossnonperformingloan | G1: GrossnonperformingloanLast | H1: Interestinsuspense | I1: InterestinsuspenseLast | J1: Totalnonperformingloan | K1: TotalnonperformingloanLast | L1: Directors | M1: DirectorsLast | N1: Employees | O1: EmployeesLast | P1: Totalinsiderloans | Q1: TotalinsiderloansLast | R1: Allowanceforloanloss | S1: Netnonperformingloans | T1: AllowanceforloanlossLast | U1: NetnonperformingloansLast | V1: othercontigentliabilities | W1: Guaranteesandcommitments | X1: totalcontingentliabilities | Y1: Corecapital | Z1: CorecapitaltoTotalassetratio | AA1: liquidityRatio | AB1: CorecapitalLast | AC1: CorecapitaltoTotalassetratioNew | AD1: CorecapitaltoTotalassetratioNewLast | AE1: Excess1 | AF1: Excess11 | AG1: Depositsliabilitiesratio | AH1: DepositsliabilitiesratioLast | AI1: CorecapitalDepositsliabilities | AJ1: CorecapitalDepositsliabilitiesLast | AK1: xcessdeficiency | AL1: xcessdeficiencyLast | AM1: Ratio2 | AN1: Ratio | AO1: ExcessLiquidity | AP1: ExcessLiquidityLast | AQ1: Minimumstatutoryratio | AR1: Minimumstatutoryratio2 | AS1: Minimumstatutoryratio3

Sheet Sheet1
B1: FORM 2H
B2: STATEMENT OF OTHER OTHER DISCLOSURES
B3: Name of Sacco Society | C3: =Data[name] -> 0
B4: Sacco Society No
B5: Financial Year | C5: =Data[FinancialYear] -> 0
B6: Start Date | C6: =Data[Date] -> 0
B7: End Date | C7: =Data[AsAt] -> 0
C9: OTHER DISCLOSURES | D9: Current Year | E9: Prior Year
D10: AMOUNT(KSHS) | E10: AMOUNT(KSHS)
B11: Ref: No
B12: 1 | C12: NON PERFORMING LOAN AND ADVANCES
B13: 1.1 | C13: Gross Non Performing Loan and Advances | D13: =Data!F2 -> 0 | E13: =Data!G2 -> 0
C14: Less:
B15: 1.2 | C15: Interest in Suspense | D15: =Data!H2 -> 0 | E15: =Data!I2 -> 0
B16: 1.3 | C16: Total Non Performing Loan and Advances(1.1-1.2) | D16: =+D13-D15 -> 0 | E16: =+E13-E15 -> 0
C17: Less:
B18: 1.4 | C18: Allowance for Loan Loss | D18: =Data!R2 -> 0 | E18: =Data!T2 -> 0
B19: 1.5 | C19: Net non performing loans (1.3-1.4) | D19: =+D16-D18 -> 0 | E19: =+E16-E18 -> 0
B20: 2 | C20: INSIDER LOANS AND ADVANCES
B21: 2.1 | C21: Directors | D21: =Data!L2 -> 0 | E21: =Data!M2 -> 0
B22: 2.2 | C22: Employees | D22: =Data!N2 -> 0 | E22: =Data!O2 -> 0
B23: 2.3 | C23: Total Insider Loans, Advances and Other Facilities | D23: =+D22+D21 -> 0 | E23: =+E22+E21 -> 0
B25: 3 | C25: OFF BALANCE SHEET ITEMS
B26: 3.1 | C26: Guarantees and Commitments
B27: 3.2 | C27: Other Contigent Liabilities
B28: 3.3 | C28: Total Contingent Liabilities
B30: 4 | C30: CAPITAL STRENGTH
B31: 4.1 | C31: Core Capital | D31: =Data!Y2 -> 0 | E31: =Data!AB2 -> 0
B32: 4.3 | C32: Core Capital to Total Asset Ratio | D32: =Data!AC2 -> 0 | E32: =Data!AD2 -> 0
B33: 4.4 | C33: Minimum Statutory Ratio | D33: 0.08 | E33: 0.08
B34: 4.5 | C34: Excess/deficiency (4.3-4.4) | D34: =+D32-D33 -> -0.08 | E34: =+E32-E33 -> -0.08
B35: 4.6 | C35: Core Capital /Deposits Liabilities Ratio | D35: =Data!AI2 -> 0 | E35: =Data!AJ2 -> 0
B36: 4.7 | C36: Minimum Statutory Ratio | D36: 0.05 | E36: 0.08
B37: 4.8 | C37: Excess/deficiency (4.6-4.7) | D37: =+D35-D36 -> -0.05 | E37: =+E35-E36 -> -0.08
B39: 5 | C39: LIQUIDITY
B40: 5.1 | C40: Liquidity Ratio | D40: =Data!AN2 -> 0 | E40: =Data!AM2 -> 0
B41: 5.2 | C41: Minimum Statutory Ratio | D41: 0.1 | E41: 0.1
B42: 5.3 | C42: Excess/deficiency (5.1-5.2) | D42: =+D40-D41 -> -0.1 | E42: =+E40-E41 -> -0.1
B45: Note: This return should be received on or before the 15th day of the month following end of every quarter
B46: We declare that this return to the best of our Knowledge and belief is correct
...
