Workbook

Sheet Data
A1: AsAt | B1: StartDate | C1: FinancialYear | D1: name | E1: CoreCapital | F1: TotalAssets | G1: TotalDeposits | H1: Nonearningassets | I1: FinancialAssets | J1: SubsidiaryandRelated | K1: Equityinvestment | L1: Otherinvestments | M1: LandBuilding | N1: OtherassetsLandBuilding | O1: LandBuildingstoAssetsRatio | P1: MaxLandBuildingtoAssetrequirement | Q1: Excessdeficiency2 | R1: FinancialinvestmentstoCorecapital | S1: MaximumfinancialinvestmentstoCorecapital | T1: ExcessCoreCapital | U1: EquityinvestmentstoCoreCapitalRatio | V1: MaxfinancialinvestmentstoTotalDepositsliablitiesRatio | W1: ExcessEquity | X1: SubsidiaryrelatedentityinvestmenttoCoreCapitalRatio | Y1: MaximumSubsidiaryinvestmenttoTotalassetsRatio | Z1: ExcessSubsidiary | AA1: OtherinvestmentstoCoreCapitalRatio | AB1: MaximumOtherinvestmentstoCoreCapital | AC1: ExcessOtherInvestment | AD1: MaxLandBuildingtoAssetrequirementNew | AE1: LandBuildingEquipmentNew | AF1: Excessdeficiency3

Sheet Return On Investment
B1: FORM 2E
B2: RETURN ON INVESTMENT
B3: NAME OF SACCO SOCIETY | C3: =Data[name] -> 0
B4: FINANCIAL YEAR | C4: =Data[FinancialYear] -> 0
B5: START DATE: | C5: =Data[StartDate] -> 0
B6: END DATE: | C6: =Data[AsAt] -> 0
A7: Ref. No.
A8: 1.1 | B8: Core Capital | C8: =SUM(Data!E2) -> 0
A9: 1.2 | B9: Total Assets | C9: =SUM(Data!F2) -> 0
A10: 1.3 | B10: Total Deposits | C10: =SUM(Data!G2) -> 0
A11: 1.4 | B11: Non earning assets | C11: =SUM(Data!H2) -> 0
A12: 1.5 | B12: Financial Assets | C12: =C13+C14+C15 -> 0
A13: 1.5.1 | B13: Subsidiary and Related Entity investments (e.g Housing ) as per Balance Sheet | C13: =SUM(Data!J2) -> 0
A14: 1.5.2 | B14: Equity investment (e.g shares bought in a legal entity ) as per Balance Sheet | C14: =SUM(Data!K2) -> 0
A15: 1.5.3 | B15: Other investments (bonds,commercial paper,investment schemes) | C15: =SUM(Data!L2) -> 0
A16: 1.6 | B16: Other assets -Land & Building, equipment (Per balance sheet) | C16: =SUM(Data!L2) -> 0
A17: 1.7 | B17: Land & Building (Per balance sheet) | C17: =SUM(Data!M2) -> 0
A19: 1.8 | B19: Land & Buildings and Equipment to total Assets Ratio (1.9/1.2)% | C19: =C16/C9 -> #DIV/0!
A20: 1.9 | B20: Maximum Land & Building and equipment to Total Asset requirement | C20: 0.1
A21: 2 | B21: Excess (deficiency) (2.1 less 2.2) | C21: =C19-C20 -> #DIV/0!
A23: 2.1 | B23: Land & Buildings to total Assets Ratio (2.0/1.2)% | C23: =C17/C9 -> #DIV/0!
A24: 2.2 | B24: Maximum Land & Building to Total Asset requirement | C24: 0.05
A25: 2.3 | B25: Excess (deficiency) (2.4 less 2.5) | C25: =C23-C24 -> #DIV/0!
A27: 2.4 | B27: Financial investments to Core capital (1.5/1.1)% | C27: =C12/C8 -> #DIV/0!
A28: 2.5 | B28: Maximum financial investments to Core capital | C28: 0.4
A29: 2.6 | B29: Excess (deficiency) (2.7 less 2.8) | C29: =C27-C28 -> #DIV/0!
A31: 2.7 | B31: Equity investments to Core Capital Ratio (1.7/1.1)% | C31: =C14/C8 -> #DIV/0!
A32: 2.8 | B32: Maximum financial investments to Total Deposits liablities Ratio % | C32: 0.2
A33: 2.9 | B33: Excess (deficiency) (3.0 less 3.1) | C33: =C31-C32 -> #DIV/0!
A35: 3 | B35: Subsidiary and related entity investment to Core Capital Ratio (1.6/1.1)% | C35: =C13/C8 -> #DIV/0!
A36: 3.1 | B36: Maximum Subsidiary investment to Total assets Ratio % | C36: 0.5
A37: 3.2 | B37: Excess (deficiency) (3.3 less 3.4) | C37: =C35-C36 -> #DIV/0!
A39: 3.3 | B39: Other investments to Core Capital Ratio (1.7/1.1)% | C39: =C21/C19 -> #DIV/0!
A40: 3.4 | B40: Maximum Other investments to Core Capital % | C40: 0.3
A41: 3.5 | B41: Excess (deficiency) (3.6 less 3.7) | C41: =C39-C40 -> #DIV/0!
A42: Note: | B42: This return should be received on or before the 15th day of the month following the end of the year
B46: AUTHORIZATION
B47: We declare that this return, to the best of our knowledge and belief is correct.
B48: sign.……..……………...………date………………..……
B49: Name of Authorizing Officer
...
